[23/Jan/2012 10:51:09] "GET /home HTTP/1.1" 200 3061
[23/Jan/2012 10:51:11] "GET /mymedia/css/site_base.css HTTP/1.1" 304 0
[23/Jan/2012 10:57:19] "GET /home HTTP/1.1" 200 3061
[23/Jan/2012 10:57:19] "GET /mymedia/css/site_base.css HTTP/1.1" 200 1690
[23/Jan/2012 11:03:04] "GET /home HTTP/1.1" 200 3061
[23/Jan/2012 11:03:05] "GET /mymedia/css/site_base.css HTTP/1.1" 200 1690
Unhandled exception in thread started by <function inner_run at 0x938a09c>
Validating models...
0 errors found

Django version 1.2.5, using settings 'tutorial.settings'
Development server is running at http://192.168.1.104:8000/
Quit the server with CONTROL-C.
Error in sys.excepthook:
Traceback (most recent call last):
  File "/usr/lib/python2.7/dist-packages/apport_python_hook.py", line 48, in apport_excepthook
    if not enabled():
TypeError: 'NoneType' object is not callable

Original exception was:
Traceback (most recent call last):
  File "/usr/lib/pymodules/python2.7/django/core/management/commands/runserver.py", line 60, in inner_run
    run(addr, int(port), handler)
  File "/usr/lib/pymodules/python2.7/django/core/servers/basehttp.py", line 721, in run
    httpd.serve_forever()
  File "/usr/lib/python2.7/SocketServer.py", line 225, in serve_forever
    r, w, e = select.select([self], [], [], poll_interval)
AttributeError: 'NoneType' object has no attribute 'select'
